{"nextFeatureIndex": 552, "attempts": 0, "errors": [{"elementID": 0, "error": "Traceback (most recent call last):\n  File \"/usr/local/lib/python3.8/dist-packages/ee/data.py\", line 330, in _execute_cloud_call\n    return call.execute(num_retries=num_retries)\n  File \"/usr/local/lib/python3.8/dist-packages/googleapiclient/_helpers.py\", line 134, in positional_wrapper\n    return wrapped(*args, **kwargs)\n  File \"/usr/local/lib/python3.8/dist-packages/googleapiclient/http.py\", line 915, in execute\n    raise HttpError(resp, content, uri=self.uri)\ngoogleapiclient.errors.HttpError: <HttpError 400 when requesting https://earthengine.googleapis.com/v1alpha/projects/earthengine-legacy/value:compute?prettyPrint=false&alt=json returned \"User memory limit exceeded.\". Details: \"User memory limit exceeded.\">\n\nDuring handling of the above exception, another exception occurred:\n\nTraceback (most recent call last):\n  File \"/geemap/data/classification/main.py\", line 210, in main\n    loopThroughAoI(featureIndex)\n  File \"/geemap/data/classification/main.py\", line 144, in loopThroughAoI\n    props['croplands_ndvi_min'] = indicators['min'].getInfo()\n  File \"/usr/local/lib/python3.8/dist-packages/ee/computedobject.py\", line 98, in getInfo\n    return data.computeValue(self)\n  File \"/usr/local/lib/python3.8/dist-packages/ee/data.py\", line 735, in computeValue\n    return _execute_cloud_call(\n  File \"/usr/local/lib/python3.8/dist-packages/ee/data.py\", line 332, in _execute_cloud_call\n    raise _translate_cloud_exception(e)\nee.ee_exception.EEException: User memory limit exceeded.\n"}, {"elementID": 0, "error": "Traceback (most recent call last):\n  File \"/usr/local/lib/python3.8/dist-packages/ee/data.py\", line 330, in _execute_cloud_call\n    return call.execute(num_retries=num_retries)\n  File \"/usr/local/lib/python3.8/dist-packages/googleapiclient/_helpers.py\", line 134, in positional_wrapper\n    return wrapped(*args, **kwargs)\n  File \"/usr/local/lib/python3.8/dist-packages/googleapiclient/http.py\", line 915, in execute\n    raise HttpError(resp, content, uri=self.uri)\ngoogleapiclient.errors.HttpError: <HttpError 400 when requesting https://earthengine.googleapis.com/v1alpha/projects/earthengine-legacy/value:compute?prettyPrint=false&alt=json returned \"User memory limit exceeded.\". Details: \"User memory limit exceeded.\">\n\nDuring handling of the above exception, another exception occurred:\n\nTraceback (most recent call last):\n  File \"/geemap/data/classification/main.py\", line 210, in main\n    loopThroughAoI(featureIndex)\n  File \"/geemap/data/classification/main.py\", line 144, in loopThroughAoI\n    props['croplands_ndvi_min'] = indicators['min'].getInfo()\n  File \"/usr/local/lib/python3.8/dist-packages/ee/computedobject.py\", line 98, in getInfo\n    return data.computeValue(self)\n  File \"/usr/local/lib/python3.8/dist-packages/ee/data.py\", line 735, in computeValue\n    return _execute_cloud_call(\n  File \"/usr/local/lib/python3.8/dist-packages/ee/data.py\", line 332, in _execute_cloud_call\n    raise _translate_cloud_exception(e)\nee.ee_exception.EEException: User memory limit exceeded.\n"}, {"elementID": 0, "error": "Traceback (most recent call last):\n  File \"/usr/local/lib/python3.8/dist-packages/ee/data.py\", line 330, in _execute_cloud_call\n    return call.execute(num_retries=num_retries)\n  File \"/usr/local/lib/python3.8/dist-packages/googleapiclient/_helpers.py\", line 134, in positional_wrapper\n    return wrapped(*args, **kwargs)\n  File \"/usr/local/lib/python3.8/dist-packages/googleapiclient/http.py\", line 915, in execute\n    raise HttpError(resp, content, uri=self.uri)\ngoogleapiclient.errors.HttpError: <HttpError 400 when requesting https://earthengine.googleapis.com/v1alpha/projects/earthengine-legacy/value:compute?prettyPrint=false&alt=json returned \"User memory limit exceeded.\". Details: \"User memory limit exceeded.\">\n\nDuring handling of the above exception, another exception occurred:\n\nTraceback (most recent call last):\n  File \"/geemap/data/classification/main.py\", line 210, in main\n    loopThroughAoI(featureIndex)\n  File \"/geemap/data/classification/main.py\", line 144, in loopThroughAoI\n    props['croplands_ndvi_min'] = indicators['min'].getInfo()\n  File \"/usr/local/lib/python3.8/dist-packages/ee/computedobject.py\", line 98, in getInfo\n    return data.computeValue(self)\n  File \"/usr/local/lib/python3.8/dist-packages/ee/data.py\", line 735, in computeValue\n    return _execute_cloud_call(\n  File \"/usr/local/lib/python3.8/dist-packages/ee/data.py\", line 332, in _execute_cloud_call\n    raise _translate_cloud_exception(e)\nee.ee_exception.EEException: User memory limit exceeded.\n"}, {"elementID": 0, "error": "Traceback (most recent call last):\n  File \"/usr/local/lib/python3.8/dist-packages/ee/data.py\", line 330, in _execute_cloud_call\n    return call.execute(num_retries=num_retries)\n  File \"/usr/local/lib/python3.8/dist-packages/googleapiclient/_helpers.py\", line 134, in positional_wrapper\n    return wrapped(*args, **kwargs)\n  File \"/usr/local/lib/python3.8/dist-packages/googleapiclient/http.py\", line 915, in execute\n    raise HttpError(resp, content, uri=self.uri)\ngoogleapiclient.errors.HttpError: <HttpError 400 when requesting https://earthengine.googleapis.com/v1alpha/projects/earthengine-legacy/value:compute?prettyPrint=false&alt=json returned \"User memory limit exceeded.\". Details: \"User memory limit exceeded.\">\n\nDuring handling of the above exception, another exception occurred:\n\nTraceback (most recent call last):\n  File \"/geemap/data/classification/main.py\", line 210, in main\n    loopThroughAoI(featureIndex)\n  File \"/geemap/data/classification/main.py\", line 144, in loopThroughAoI\n    props['croplands_ndvi_min'] = indicators['min'].getInfo()\n  File \"/usr/local/lib/python3.8/dist-packages/ee/computedobject.py\", line 98, in getInfo\n    return data.computeValue(self)\n  File \"/usr/local/lib/python3.8/dist-packages/ee/data.py\", line 735, in computeValue\n    return _execute_cloud_call(\n  File \"/usr/local/lib/python3.8/dist-packages/ee/data.py\", line 332, in _execute_cloud_call\n    raise _translate_cloud_exception(e)\nee.ee_exception.EEException: User memory limit exceeded.\n"}, {"elementID": 0, "error": "Traceback (most recent call last):\n  File \"/usr/local/lib/python3.8/dist-packages/ee/data.py\", line 330, in _execute_cloud_call\n    return call.execute(num_retries=num_retries)\n  File \"/usr/local/lib/python3.8/dist-packages/googleapiclient/_helpers.py\", line 134, in positional_wrapper\n    return wrapped(*args, **kwargs)\n  File \"/usr/local/lib/python3.8/dist-packages/googleapiclient/http.py\", line 915, in execute\n    raise HttpError(resp, content, uri=self.uri)\ngoogleapiclient.errors.HttpError: <HttpError 400 when requesting https://earthengine.googleapis.com/v1alpha/projects/earthengine-legacy/value:compute?prettyPrint=false&alt=json returned \"User memory limit exceeded.\". Details: \"User memory limit exceeded.\">\n\nDuring handling of the above exception, another exception occurred:\n\nTraceback (most recent call last):\n  File \"/geemap/data/classification/main.py\", line 210, in main\n    loopThroughAoI(featureIndex)\n  File \"/geemap/data/classification/main.py\", line 144, in loopThroughAoI\n    props['croplands_ndvi_min'] = indicators['min'].getInfo()\n  File \"/usr/local/lib/python3.8/dist-packages/ee/computedobject.py\", line 98, in getInfo\n    return data.computeValue(self)\n  File \"/usr/local/lib/python3.8/dist-packages/ee/data.py\", line 735, in computeValue\n    return _execute_cloud_call(\n  File \"/usr/local/lib/python3.8/dist-packages/ee/data.py\", line 332, in _execute_cloud_call\n    raise _translate_cloud_exception(e)\nee.ee_exception.EEException: User memory limit exceeded.\n"}, {"elementID": 0, "error": "Traceback (most recent call last):\n  File \"/usr/local/lib/python3.8/dist-packages/ee/data.py\", line 330, in _execute_cloud_call\n    return call.execute(num_retries=num_retries)\n  File \"/usr/local/lib/python3.8/dist-packages/googleapiclient/_helpers.py\", line 134, in positional_wrapper\n    return wrapped(*args, **kwargs)\n  File \"/usr/local/lib/python3.8/dist-packages/googleapiclient/http.py\", line 915, in execute\n    raise HttpError(resp, content, uri=self.uri)\ngoogleapiclient.errors.HttpError: <HttpError 400 when requesting https://earthengine.googleapis.com/v1alpha/projects/earthengine-legacy/value:compute?prettyPrint=false&alt=json returned \"User memory limit exceeded.\". Details: \"User memory limit exceeded.\">\n\nDuring handling of the above exception, another exception occurred:\n\nTraceback (most recent call last):\n  File \"/geemap/data/classification/main.py\", line 210, in main\n    loopThroughAoI(featureIndex)\n  File \"/geemap/data/classification/main.py\", line 144, in loopThroughAoI\n    props['croplands_ndvi_min'] = indicators['min'].getInfo()\n  File \"/usr/local/lib/python3.8/dist-packages/ee/computedobject.py\", line 98, in getInfo\n    return data.computeValue(self)\n  File \"/usr/local/lib/python3.8/dist-packages/ee/data.py\", line 735, in computeValue\n    return _execute_cloud_call(\n  File \"/usr/local/lib/python3.8/dist-packages/ee/data.py\", line 332, in _execute_cloud_call\n    raise _translate_cloud_exception(e)\nee.ee_exception.EEException: User memory limit exceeded.\n"}, {"elementID": 0, "error": "Traceback (most recent call last):\n  File \"/usr/lib/python3/dist-packages/urllib3/connection.py\", line 159, in _new_conn\n    conn = connection.create_connection(\n  File \"/usr/lib/python3/dist-packages/urllib3/util/connection.py\", line 61, in create_connection\n    for res in socket.getaddrinfo(host, port, family, socket.SOCK_STREAM):\n  File \"/usr/lib/python3.8/socket.py\", line 918, in getaddrinfo\n    for res in _socket.getaddrinfo(host, port, family, type, proto, flags):\nsocket.gaierror: [Errno -2] Name or service not known\n\nDuring handling of the above exception, another exception occurred:\n\nTraceback (most recent call last):\n  File \"/usr/local/lib/python3.8/dist-packages/httplib2shim/__init__.py\", line 140, in _conn_request\n    urllib3_response = self.pool.request(\n  File \"/usr/lib/python3/dist-packages/urllib3/request.py\", line 79, in request\n    return self.request_encode_body(\n  File \"/usr/lib/python3/dist-packages/urllib3/request.py\", line 171, in request_encode_body\n    return self.urlopen(method, url, **extra_kw)\n  File \"/usr/lib/python3/dist-packages/urllib3/poolmanager.py\", line 330, in urlopen\n    response = conn.urlopen(method, u.request_uri, **kw)\n  File \"/usr/lib/python3/dist-packages/urllib3/connectionpool.py\", line 719, in urlopen\n    retries = retries.increment(\n  File \"/usr/lib/python3/dist-packages/urllib3/util/retry.py\", line 376, in increment\n    raise six.reraise(type(error), error, _stacktrace)\n  File \"/usr/lib/python3/dist-packages/six.py\", line 703, in reraise\n    raise value\n  File \"/usr/lib/python3/dist-packages/urllib3/connectionpool.py\", line 665, in urlopen\n    httplib_response = self._make_request(\n  File \"/usr/lib/python3/dist-packages/urllib3/connectionpool.py\", line 376, in _make_request\n    self._validate_conn(conn)\n  File \"/usr/lib/python3/dist-packages/urllib3/connectionpool.py\", line 996, in _validate_conn\n    conn.connect()\n  File \"/usr/lib/python3/dist-packages/urllib3/connection.py\", line 314, in connect\n    conn = self._new_conn()\n  File \"/usr/lib/python3/dist-packages/urllib3/connection.py\", line 171, in _new_conn\n    raise NewConnectionError(\nurllib3.exceptions.NewConnectionError: <urllib3.connection.VerifiedHTTPSConnection object at 0x7f890f3f2d30>: Failed to establish a new connection: [Errno -2] Name or service not known\n\nDuring handling of the above exception, another exception occurred:\n\nTraceback (most recent call last):\n  File \"/usr/local/lib/python3.8/dist-packages/google_auth_httplib2.py\", line 119, in __call__\n    response, data = self.http.request(\n  File \"/usr/local/lib/python3.8/dist-packages/httplib2/__init__.py\", line 1701, in request\n    (response, content) = self._request(\n  File \"/usr/local/lib/python3.8/dist-packages/httplib2/__init__.py\", line 1421, in _request\n    (response, content) = self._conn_request(conn, request_uri, method, body, headers)\n  File \"/usr/local/lib/python3.8/dist-packages/httplib2shim/__init__.py\", line 154, in _conn_request\n    raise _map_exception(e)\nhttplib2.error.ServerNotFoundError: Unable to find hostname.\n\nDuring handling of the above exception, another exception occurred:\n\nTraceback (most recent call last):\n  File \"/geemap/data/classification/main.py\", line 210, in main\n    loopThroughAoI(featureIndex)\n  File \"/geemap/data/classification/main.py\", line 148, in loopThroughAoI\n    props['croplands_ndvi_stddev'] = indicators['stdDev'].getInfo()\n  File \"/usr/local/lib/python3.8/dist-packages/ee/computedobject.py\", line 98, in getInfo\n    return data.computeValue(self)\n  File \"/usr/local/lib/python3.8/dist-packages/ee/data.py\", line 735, in computeValue\n    return _execute_cloud_call(\n  File \"/usr/local/lib/python3.8/dist-packages/ee/data.py\", line 330, in _execute_cloud_call\n    return call.execute(num_retries=num_retries)\n  File \"/usr/local/lib/python3.8/dist-packages/googleapiclient/_helpers.py\", line 134, in positional_wrapper\n    return wrapped(*args, **kwargs)\n  File \"/usr/local/lib/python3.8/dist-packages/googleapiclient/http.py\", line 900, in execute\n    resp, content = _retry_request(\n  File \"/usr/local/lib/python3.8/dist-packages/googleapiclient/http.py\", line 177, in _retry_request\n    resp, content = http.request(uri, method, *args, **kwargs)\n  File \"/usr/local/lib/python3.8/dist-packages/google_auth_httplib2.py\", line 209, in request\n    self.credentials.before_request(self._request, method, uri, request_headers)\n  File \"/usr/local/lib/python3.8/dist-packages/google/auth/credentials.py\", line 133, in before_request\n    self.refresh(request)\n  File \"/usr/local/lib/python3.8/dist-packages/google/oauth2/credentials.py\", line 293, in refresh\n    ) = reauth.refresh_grant(\n  File \"/usr/local/lib/python3.8/dist-packages/google/oauth2/reauth.py\", line 318, in refresh_grant\n    response_status_ok, response_data = _client._token_endpoint_request_no_throw(\n  File \"/usr/local/lib/python3.8/dist-packages/google/oauth2/_client.py\", line 115, in _token_endpoint_request_no_throw\n    response = request(method=\"POST\", url=token_uri, headers=headers, body=body)\n  File \"/usr/local/lib/python3.8/dist-packages/google_auth_httplib2.py\", line 126, in __call__\n    raise exceptions.TransportError(exc)\ngoogle.auth.exceptions.TransportError: Unable to find hostname.\n"}, {"elementID": 0, "error": "Traceback (most recent call last):\n  File \"/usr/lib/python3/dist-packages/urllib3/connection.py\", line 159, in _new_conn\n    conn = connection.create_connection(\n  File \"/usr/lib/python3/dist-packages/urllib3/util/connection.py\", line 61, in create_connection\n    for res in socket.getaddrinfo(host, port, family, socket.SOCK_STREAM):\n  File \"/usr/lib/python3.8/socket.py\", line 918, in getaddrinfo\n    for res in _socket.getaddrinfo(host, port, family, type, proto, flags):\nsocket.gaierror: [Errno -2] Name or service not known\n\nDuring handling of the above exception, another exception occurred:\n\nTraceback (most recent call last):\n  File \"/usr/local/lib/python3.8/dist-packages/httplib2shim/__init__.py\", line 140, in _conn_request\n    urllib3_response = self.pool.request(\n  File \"/usr/lib/python3/dist-packages/urllib3/request.py\", line 79, in request\n    return self.request_encode_body(\n  File \"/usr/lib/python3/dist-packages/urllib3/request.py\", line 171, in request_encode_body\n    return self.urlopen(method, url, **extra_kw)\n  File \"/usr/lib/python3/dist-packages/urllib3/poolmanager.py\", line 330, in urlopen\n    response = conn.urlopen(method, u.request_uri, **kw)\n  File \"/usr/lib/python3/dist-packages/urllib3/connectionpool.py\", line 719, in urlopen\n    retries = retries.increment(\n  File \"/usr/lib/python3/dist-packages/urllib3/util/retry.py\", line 376, in increment\n    raise six.reraise(type(error), error, _stacktrace)\n  File \"/usr/lib/python3/dist-packages/six.py\", line 703, in reraise\n    raise value\n  File \"/usr/lib/python3/dist-packages/urllib3/connectionpool.py\", line 665, in urlopen\n    httplib_response = self._make_request(\n  File \"/usr/lib/python3/dist-packages/urllib3/connectionpool.py\", line 376, in _make_request\n    self._validate_conn(conn)\n  File \"/usr/lib/python3/dist-packages/urllib3/connectionpool.py\", line 996, in _validate_conn\n    conn.connect()\n  File \"/usr/lib/python3/dist-packages/urllib3/connection.py\", line 314, in connect\n    conn = self._new_conn()\n  File \"/usr/lib/python3/dist-packages/urllib3/connection.py\", line 171, in _new_conn\n    raise NewConnectionError(\nurllib3.exceptions.NewConnectionError: <urllib3.connection.VerifiedHTTPSConnection object at 0x7f890e696dc0>: Failed to establish a new connection: [Errno -2] Name or service not known\n\nDuring handling of the above exception, another exception occurred:\n\nTraceback (most recent call last):\n  File \"/usr/local/lib/python3.8/dist-packages/google_auth_httplib2.py\", line 119, in __call__\n    response, data = self.http.request(\n  File \"/usr/local/lib/python3.8/dist-packages/httplib2/__init__.py\", line 1701, in request\n    (response, content) = self._request(\n  File \"/usr/local/lib/python3.8/dist-packages/httplib2/__init__.py\", line 1421, in _request\n    (response, content) = self._conn_request(conn, request_uri, method, body, headers)\n  File \"/usr/local/lib/python3.8/dist-packages/httplib2shim/__init__.py\", line 154, in _conn_request\n    raise _map_exception(e)\nhttplib2.error.ServerNotFoundError: Unable to find hostname.\n\nDuring handling of the above exception, another exception occurred:\n\nTraceback (most recent call last):\n  File \"/geemap/data/classification/main.py\", line 210, in main\n    loopThroughAoI(featureIndex)\n  File \"/geemap/data/classification/main.py\", line 128, in loopThroughAoI\n    if subCroplands_Classification.size().getInfo() > 0:\n  File \"/usr/local/lib/python3.8/dist-packages/ee/computedobject.py\", line 98, in getInfo\n    return data.computeValue(self)\n  File \"/usr/local/lib/python3.8/dist-packages/ee/data.py\", line 735, in computeValue\n    return _execute_cloud_call(\n  File \"/usr/local/lib/python3.8/dist-packages/ee/data.py\", line 330, in _execute_cloud_call\n    return call.execute(num_retries=num_retries)\n  File \"/usr/local/lib/python3.8/dist-packages/googleapiclient/_helpers.py\", line 134, in positional_wrapper\n    return wrapped(*args, **kwargs)\n  File \"/usr/local/lib/python3.8/dist-packages/googleapiclient/http.py\", line 900, in execute\n    resp, content = _retry_request(\n  File \"/usr/local/lib/python3.8/dist-packages/googleapiclient/http.py\", line 177, in _retry_request\n    resp, content = http.request(uri, method, *args, **kwargs)\n  File \"/usr/local/lib/python3.8/dist-packages/google_auth_httplib2.py\", line 209, in request\n    self.credentials.before_request(self._request, method, uri, request_headers)\n  File \"/usr/local/lib/python3.8/dist-packages/google/auth/credentials.py\", line 133, in before_request\n    self.refresh(request)\n  File \"/usr/local/lib/python3.8/dist-packages/google/oauth2/credentials.py\", line 293, in refresh\n    ) = reauth.refresh_grant(\n  File \"/usr/local/lib/python3.8/dist-packages/google/oauth2/reauth.py\", line 318, in refresh_grant\n    response_status_ok, response_data = _client._token_endpoint_request_no_throw(\n  File \"/usr/local/lib/python3.8/dist-packages/google/oauth2/_client.py\", line 115, in _token_endpoint_request_no_throw\n    response = request(method=\"POST\", url=token_uri, headers=headers, body=body)\n  File \"/usr/local/lib/python3.8/dist-packages/google_auth_httplib2.py\", line 126, in __call__\n    raise exceptions.TransportError(exc)\ngoogle.auth.exceptions.TransportError: Unable to find hostname.\n"}, {"elementID": 0, "error": "Traceback (most recent call last):\n  File \"/usr/lib/python3/dist-packages/urllib3/connection.py\", line 159, in _new_conn\n    conn = connection.create_connection(\n  File \"/usr/lib/python3/dist-packages/urllib3/util/connection.py\", line 61, in create_connection\n    for res in socket.getaddrinfo(host, port, family, socket.SOCK_STREAM):\n  File \"/usr/lib/python3.8/socket.py\", line 918, in getaddrinfo\n    for res in _socket.getaddrinfo(host, port, family, type, proto, flags):\nsocket.gaierror: [Errno -2] Name or service not known\n\nDuring handling of the above exception, another exception occurred:\n\nTraceback (most recent call last):\n  File \"/usr/local/lib/python3.8/dist-packages/httplib2shim/__init__.py\", line 140, in _conn_request\n    urllib3_response = self.pool.request(\n  File \"/usr/lib/python3/dist-packages/urllib3/request.py\", line 79, in request\n    return self.request_encode_body(\n  File \"/usr/lib/python3/dist-packages/urllib3/request.py\", line 171, in request_encode_body\n    return self.urlopen(method, url, **extra_kw)\n  File \"/usr/lib/python3/dist-packages/urllib3/poolmanager.py\", line 330, in urlopen\n    response = conn.urlopen(method, u.request_uri, **kw)\n  File \"/usr/lib/python3/dist-packages/urllib3/connectionpool.py\", line 719, in urlopen\n    retries = retries.increment(\n  File \"/usr/lib/python3/dist-packages/urllib3/util/retry.py\", line 376, in increment\n    raise six.reraise(type(error), error, _stacktrace)\n  File \"/usr/lib/python3/dist-packages/six.py\", line 703, in reraise\n    raise value\n  File \"/usr/lib/python3/dist-packages/urllib3/connectionpool.py\", line 665, in urlopen\n    httplib_response = self._make_request(\n  File \"/usr/lib/python3/dist-packages/urllib3/connectionpool.py\", line 376, in _make_request\n    self._validate_conn(conn)\n  File \"/usr/lib/python3/dist-packages/urllib3/connectionpool.py\", line 996, in _validate_conn\n    conn.connect()\n  File \"/usr/lib/python3/dist-packages/urllib3/connection.py\", line 314, in connect\n    conn = self._new_conn()\n  File \"/usr/lib/python3/dist-packages/urllib3/connection.py\", line 171, in _new_conn\n    raise NewConnectionError(\nurllib3.exceptions.NewConnectionError: <urllib3.connection.VerifiedHTTPSConnection object at 0x7f890e696910>: Failed to establish a new connection: [Errno -2] Name or service not known\n\nDuring handling of the above exception, another exception occurred:\n\nTraceback (most recent call last):\n  File \"/usr/local/lib/python3.8/dist-packages/google_auth_httplib2.py\", line 119, in __call__\n    response, data = self.http.request(\n  File \"/usr/local/lib/python3.8/dist-packages/httplib2/__init__.py\", line 1701, in request\n    (response, content) = self._request(\n  File \"/usr/local/lib/python3.8/dist-packages/httplib2/__init__.py\", line 1421, in _request\n    (response, content) = self._conn_request(conn, request_uri, method, body, headers)\n  File \"/usr/local/lib/python3.8/dist-packages/httplib2shim/__init__.py\", line 154, in _conn_request\n    raise _map_exception(e)\nhttplib2.error.ServerNotFoundError: Unable to find hostname.\n\nDuring handling of the above exception, another exception occurred:\n\nTraceback (most recent call last):\n  File \"/geemap/data/classification/main.py\", line 210, in main\n    loopThroughAoI(featureIndex)\n  File \"/geemap/data/classification/main.py\", line 128, in loopThroughAoI\n    if subCroplands_Classification.size().getInfo() > 0:\n  File \"/usr/local/lib/python3.8/dist-packages/ee/computedobject.py\", line 98, in getInfo\n    return data.computeValue(self)\n  File \"/usr/local/lib/python3.8/dist-packages/ee/data.py\", line 735, in computeValue\n    return _execute_cloud_call(\n  File \"/usr/local/lib/python3.8/dist-packages/ee/data.py\", line 330, in _execute_cloud_call\n    return call.execute(num_retries=num_retries)\n  File \"/usr/local/lib/python3.8/dist-packages/googleapiclient/_helpers.py\", line 134, in positional_wrapper\n    return wrapped(*args, **kwargs)\n  File \"/usr/local/lib/python3.8/dist-packages/googleapiclient/http.py\", line 900, in execute\n    resp, content = _retry_request(\n  File \"/usr/local/lib/python3.8/dist-packages/googleapiclient/http.py\", line 177, in _retry_request\n    resp, content = http.request(uri, method, *args, **kwargs)\n  File \"/usr/local/lib/python3.8/dist-packages/google_auth_httplib2.py\", line 209, in request\n    self.credentials.before_request(self._request, method, uri, request_headers)\n  File \"/usr/local/lib/python3.8/dist-packages/google/auth/credentials.py\", line 133, in before_request\n    self.refresh(request)\n  File \"/usr/local/lib/python3.8/dist-packages/google/oauth2/credentials.py\", line 293, in refresh\n    ) = reauth.refresh_grant(\n  File \"/usr/local/lib/python3.8/dist-packages/google/oauth2/reauth.py\", line 318, in refresh_grant\n    response_status_ok, response_data = _client._token_endpoint_request_no_throw(\n  File \"/usr/local/lib/python3.8/dist-packages/google/oauth2/_client.py\", line 115, in _token_endpoint_request_no_throw\n    response = request(method=\"POST\", url=token_uri, headers=headers, body=body)\n  File \"/usr/local/lib/python3.8/dist-packages/google_auth_httplib2.py\", line 126, in __call__\n    raise exceptions.TransportError(exc)\ngoogle.auth.exceptions.TransportError: Unable to find hostname.\n"}, {"elementID": 0, "error": "Traceback (most recent call last):\n  File \"/usr/lib/python3/dist-packages/urllib3/connection.py\", line 159, in _new_conn\n    conn = connection.create_connection(\n  File \"/usr/lib/python3/dist-packages/urllib3/util/connection.py\", line 61, in create_connection\n    for res in socket.getaddrinfo(host, port, family, socket.SOCK_STREAM):\n  File \"/usr/lib/python3.8/socket.py\", line 918, in getaddrinfo\n    for res in _socket.getaddrinfo(host, port, family, type, proto, flags):\nsocket.gaierror: [Errno -2] Name or service not known\n\nDuring handling of the above exception, another exception occurred:\n\nTraceback (most recent call last):\n  File \"/usr/local/lib/python3.8/dist-packages/httplib2shim/__init__.py\", line 140, in _conn_request\n    urllib3_response = self.pool.request(\n  File \"/usr/lib/python3/dist-packages/urllib3/request.py\", line 79, in request\n    return self.request_encode_body(\n  File \"/usr/lib/python3/dist-packages/urllib3/request.py\", line 171, in request_encode_body\n    return self.urlopen(method, url, **extra_kw)\n  File \"/usr/lib/python3/dist-packages/urllib3/poolmanager.py\", line 330, in urlopen\n    response = conn.urlopen(method, u.request_uri, **kw)\n  File \"/usr/lib/python3/dist-packages/urllib3/connectionpool.py\", line 719, in urlopen\n    retries = retries.increment(\n  File \"/usr/lib/python3/dist-packages/urllib3/util/retry.py\", line 376, in increment\n    raise six.reraise(type(error), error, _stacktrace)\n  File \"/usr/lib/python3/dist-packages/six.py\", line 703, in reraise\n    raise value\n  File \"/usr/lib/python3/dist-packages/urllib3/connectionpool.py\", line 665, in urlopen\n    httplib_response = self._make_request(\n  File \"/usr/lib/python3/dist-packages/urllib3/connectionpool.py\", line 376, in _make_request\n    self._validate_conn(conn)\n  File \"/usr/lib/python3/dist-packages/urllib3/connectionpool.py\", line 996, in _validate_conn\n    conn.connect()\n  File \"/usr/lib/python3/dist-packages/urllib3/connection.py\", line 314, in connect\n    conn = self._new_conn()\n  File \"/usr/lib/python3/dist-packages/urllib3/connection.py\", line 171, in _new_conn\n    raise NewConnectionError(\nurllib3.exceptions.NewConnectionError: <urllib3.connection.VerifiedHTTPSConnection object at 0x7f890cec3400>: Failed to establish a new connection: [Errno -2] Name or service not known\n\nDuring handling of the above exception, another exception occurred:\n\nTraceback (most recent call last):\n  File \"/usr/local/lib/python3.8/dist-packages/google_auth_httplib2.py\", line 119, in __call__\n    response, data = self.http.request(\n  File \"/usr/local/lib/python3.8/dist-packages/httplib2/__init__.py\", line 1701, in request\n    (response, content) = self._request(\n  File \"/usr/local/lib/python3.8/dist-packages/httplib2/__init__.py\", line 1421, in _request\n    (response, content) = self._conn_request(conn, request_uri, method, body, headers)\n  File \"/usr/local/lib/python3.8/dist-packages/httplib2shim/__init__.py\", line 154, in _conn_request\n    raise _map_exception(e)\nhttplib2.error.ServerNotFoundError: Unable to find hostname.\n\nDuring handling of the above exception, another exception occurred:\n\nTraceback (most recent call last):\n  File \"/geemap/data/classification/main.py\", line 210, in main\n    loopThroughAoI(featureIndex)\n  File \"/geemap/data/classification/main.py\", line 128, in loopThroughAoI\n    if subCroplands_Classification.size().getInfo() > 0:\n  File \"/usr/local/lib/python3.8/dist-packages/ee/computedobject.py\", line 98, in getInfo\n    return data.computeValue(self)\n  File \"/usr/local/lib/python3.8/dist-packages/ee/data.py\", line 735, in computeValue\n    return _execute_cloud_call(\n  File \"/usr/local/lib/python3.8/dist-packages/ee/data.py\", line 330, in _execute_cloud_call\n    return call.execute(num_retries=num_retries)\n  File \"/usr/local/lib/python3.8/dist-packages/googleapiclient/_helpers.py\", line 134, in positional_wrapper\n    return wrapped(*args, **kwargs)\n  File \"/usr/local/lib/python3.8/dist-packages/googleapiclient/http.py\", line 900, in execute\n    resp, content = _retry_request(\n  File \"/usr/local/lib/python3.8/dist-packages/googleapiclient/http.py\", line 177, in _retry_request\n    resp, content = http.request(uri, method, *args, **kwargs)\n  File \"/usr/local/lib/python3.8/dist-packages/google_auth_httplib2.py\", line 209, in request\n    self.credentials.before_request(self._request, method, uri, request_headers)\n  File \"/usr/local/lib/python3.8/dist-packages/google/auth/credentials.py\", line 133, in before_request\n    self.refresh(request)\n  File \"/usr/local/lib/python3.8/dist-packages/google/oauth2/credentials.py\", line 293, in refresh\n    ) = reauth.refresh_grant(\n  File \"/usr/local/lib/python3.8/dist-packages/google/oauth2/reauth.py\", line 318, in refresh_grant\n    response_status_ok, response_data = _client._token_endpoint_request_no_throw(\n  File \"/usr/local/lib/python3.8/dist-packages/google/oauth2/_client.py\", line 115, in _token_endpoint_request_no_throw\n    response = request(method=\"POST\", url=token_uri, headers=headers, body=body)\n  File \"/usr/local/lib/python3.8/dist-packages/google_auth_httplib2.py\", line 126, in __call__\n    raise exceptions.TransportError(exc)\ngoogle.auth.exceptions.TransportError: Unable to find hostname.\n"}, {"elementID": 0, "error": "Traceback (most recent call last):\n  File \"/usr/local/lib/python3.8/dist-packages/ee/data.py\", line 330, in _execute_cloud_call\n    return call.execute(num_retries=num_retries)\n  File \"/usr/local/lib/python3.8/dist-packages/googleapiclient/_helpers.py\", line 134, in positional_wrapper\n    return wrapped(*args, **kwargs)\n  File \"/usr/local/lib/python3.8/dist-packages/googleapiclient/http.py\", line 915, in execute\n    raise HttpError(resp, content, uri=self.uri)\ngoogleapiclient.errors.HttpError: <HttpError 400 when requesting https://earthengine.googleapis.com/v1alpha/projects/earthengine-legacy/value:compute?prettyPrint=false&alt=json returned \"User memory limit exceeded.\". Details: \"User memory limit exceeded.\">\n\nDuring handling of the above exception, another exception occurred:\n\nTraceback (most recent call last):\n  File \"/geemap/data/classification/main.py\", line 210, in main\n    loopThroughAoI(featureIndex)\n  File \"/geemap/data/classification/main.py\", line 144, in loopThroughAoI\n    props['croplands_ndvi_min'] = indicators['min'].getInfo()\n  File \"/usr/local/lib/python3.8/dist-packages/ee/computedobject.py\", line 98, in getInfo\n    return data.computeValue(self)\n  File \"/usr/local/lib/python3.8/dist-packages/ee/data.py\", line 735, in computeValue\n    return _execute_cloud_call(\n  File \"/usr/local/lib/python3.8/dist-packages/ee/data.py\", line 332, in _execute_cloud_call\n    raise _translate_cloud_exception(e)\nee.ee_exception.EEException: User memory limit exceeded.\n"}, {"elementID": 0, "error": "Traceback (most recent call last):\n  File \"/usr/local/lib/python3.8/dist-packages/ee/data.py\", line 330, in _execute_cloud_call\n    return call.execute(num_retries=num_retries)\n  File \"/usr/local/lib/python3.8/dist-packages/googleapiclient/_helpers.py\", line 134, in positional_wrapper\n    return wrapped(*args, **kwargs)\n  File \"/usr/local/lib/python3.8/dist-packages/googleapiclient/http.py\", line 915, in execute\n    raise HttpError(resp, content, uri=self.uri)\ngoogleapiclient.errors.HttpError: <HttpError 400 when requesting https://earthengine.googleapis.com/v1alpha/projects/earthengine-legacy/value:compute?prettyPrint=false&alt=json returned \"User memory limit exceeded.\". Details: \"User memory limit exceeded.\">\n\nDuring handling of the above exception, another exception occurred:\n\nTraceback (most recent call last):\n  File \"/geemap/data/classification/main.py\", line 210, in main\n    loopThroughAoI(featureIndex)\n  File \"/geemap/data/classification/main.py\", line 144, in loopThroughAoI\n    props['croplands_ndvi_min'] = indicators['min'].getInfo()\n  File \"/usr/local/lib/python3.8/dist-packages/ee/computedobject.py\", line 98, in getInfo\n    return data.computeValue(self)\n  File \"/usr/local/lib/python3.8/dist-packages/ee/data.py\", line 735, in computeValue\n    return _execute_cloud_call(\n  File \"/usr/local/lib/python3.8/dist-packages/ee/data.py\", line 332, in _execute_cloud_call\n    raise _translate_cloud_exception(e)\nee.ee_exception.EEException: User memory limit exceeded.\n"}]}